<?xml version="1.0" encoding="utf-8"?>

<robot name="gummi">

 <link name="base_link">
    <visual>
      <origin rpy="0.0 0.0 0.0" xyz="0.0 0.0 0.005"/>
      <geometry>
	<cylinder length="0.01" radius="0.065" />
      </geometry>
      <material name="">
        <color rgba="0.5 0.1 0.5 1.0"/>
      </material>
    </visual>
    <collision>
      <origin rpy="0.0 0.0 0.0" xyz="0.0 0.0 0.005"/>
      <geometry>
        <cylinder length="0.01" radius="0.065" />
      </geometry>
    </collision>
  </link>

 <link name="shoulder_preroll">
    <visual>
      <origin rpy="0.0 0.0 0.0" xyz="0.0 0.0 0.035"/>
      <geometry>
	<cylinder length="0.01" radius="0.065" />
      </geometry>
      <material name="">
        <color rgba="0.5 0.5 0.5 1.0"/>
      </material>
    </visual>
    <collision>
      <origin rpy="0.0 0.0 0.0" xyz="0.0 0.0 0.035"/>
      <geometry>
        <cylinder length="0.01" radius="0.065" />
      </geometry>
    </collision>
  </link>

  <link name="shoulder">
    <visual>
      <origin rpy="0.0 0.0 0.0" xyz="0.0 0.0 0.0"/>
      <geometry>
	<cylinder length="0.12" radius="0.06" />
      </geometry>
      <material name="">
        <color rgba="0.0 0.1 0.0 1.0"/>
      </material>
    </visual>
    <collision>
      <origin rpy="0.0 0.0 0.0" xyz="0.0 0.0 0.0"/>
      <geometry>
        <cylinder length="0.12" radius="0.06" />
      </geometry>
    </collision>
    <inertial>
      <origin rpy="0.0 0.0 0.0" xyz="0.0 0.0 0.0"/>
      <mass value="1"/>
      <inertia ixx="1.0" ixy="0.0" ixz="0.0" iyy="1.0" iyz="0.0" izz="1.0"/>
    </inertial>
  </link>

  <link name="upperarm_preroll">
    <visual>
      <origin rpy="0.0 0.0 0.0" xyz="0.0 0.0 0.0"/>
      <geometry>
	<cylinder length="0.06" radius="0.03" />
      </geometry>
      <material name="">
        <color rgba="0.0 0.2 0.0 1.0"/>
      </material>
    </visual>
    <collision>
      <origin rpy="0.0 0.0 0.0" xyz="0.0 0.0 0.0"/>
      <geometry>
        <cylinder length="0.06" radius="0.03" />
      </geometry>
    </collision>
    <inertial>
      <origin rpy="0.0 0.0 0.0" xyz="0.0 0.0 0.0"/>
      <mass value="1"/>
      <inertia ixx="1.0" ixy="0.0" ixz="0.0" iyy="1.0" iyz="0.0" izz="1.0"/>
    </inertial>
  </link>

  <link name="upperarm">
    <visual>
      <origin rpy="0.0 0.0 0.0" xyz="0.0 0.0 0.08"/>
      <geometry>
	<cylinder length="0.16" radius="0.04" />
      </geometry>
      <material name="">
        <color rgba="0.0 0.3 0.0 1.0"/>
      </material>
    </visual>
    <collision>
      <origin rpy="0.0 0.0 0.0" xyz="0.0 0.0 0.08"/>
      <geometry>
        <cylinder length="0.16" radius="0.04" />
      </geometry>
    </collision>
    <inertial>
      <origin rpy="0.0 0.0 0.0" xyz="0.0 0.0 0.0"/>
      <mass value="1"/>
      <inertia ixx="1.0" ixy="0.0" ixz="0.0" iyy="1.0" iyz="0.0" izz="1.0"/>
    </inertial>
  </link>

  <link name="lowerarm_preroll">
    <visual>
      <origin rpy="0.0 0.0 0.0" xyz="0.0 0.0 0.0"/>
      <geometry>
	<cylinder length="0.06" radius="0.03" />
      </geometry>
      <material name="">
        <color rgba="0.0 0.4 0.0 1.0"/>
      </material>
    </visual>
    <collision>
      <origin rpy="0.0 0.0 0.0" xyz="0.0 0.0 0.0"/>
      <geometry>
        <cylinder length="0.06" radius="0.03" />
      </geometry>
    </collision>
    <inertial>
      <origin rpy="0.0 0.0 0.0" xyz="0.0 0.0 0.0"/>
      <mass value="1"/>
      <inertia ixx="1.0" ixy="0.0" ixz="0.0" iyy="1.0" iyz="0.0" izz="1.0"/>
    </inertial>
  </link>

  <link name="lowerarm">
    <visual>
      <origin rpy="0.0 0.0 0.0" xyz="0.0 0.0 0.055"/>
      <geometry>
	<cylinder length="0.11" radius="0.04" />
      </geometry>
      <material name="">
        <color rgba="0.0 0.5 0.0 1.0"/>
      </material>
    </visual>
    <collision>
      <origin rpy="0.0 0.0 0.0" xyz="0.0 0.0 0.055"/>
      <geometry>
        <cylinder length="0.11" radius="0.04" />
      </geometry>
    </collision>
    <inertial>
      <origin rpy="0.0 0.0 0.0" xyz="0.0 0.0 0.0"/>
      <mass value="1"/>
      <inertia ixx="1.0" ixy="0.0" ixz="0.0" iyy="1.0" iyz="0.0" izz="1.0"/>
    </inertial>
  </link>

  <link name="wrist">
    <visual>
      <origin rpy="0.0 0.0 0.0" xyz="0.0 0.0 0.0"/>
      <geometry>
	<cylinder length="0.04" radius="0.02" />
      </geometry>
      <material name="">
        <color rgba="0.0 0.6 0.0 1.0"/>
      </material>
    </visual>
    <collision>
      <origin rpy="0.0 0.0 0.0" xyz="0.0 0.0 0.0"/>
      <geometry>
        <cylinder length="0.04" radius="0.02" />
      </geometry>
    </collision>
    <inertial>
      <origin rpy="0.0 0.0 0.0" xyz="0.0 0.0 0.0"/>
      <mass value="1"/>
      <inertia ixx="1.0" ixy="0.0" ixz="0.0" iyy="1.0" iyz="0.0" izz="1.0"/>
    </inertial>
  </link>

  <link name="coupling">
    <visual>
      <origin rpy="0.0 1.57080 0.0" xyz="0.0 0.0 0.0"/>
      <geometry>
	<cylinder length="0.01" radius="0.02" />
      </geometry>
      <material name="">
        <color rgba="0.0 0.7 0.0 1.0"/>
      </material>
    </visual>
    <collision>
      <origin rpy="0.0 1.57080 0.0" xyz="0.0 0.0 0.0"/>
      <geometry>
        <cylinder length="0.01" radius="0.02" />
      </geometry>
    </collision>
    <inertial>
      <origin rpy="0.0 0.0 0.0" xyz="0.0 0.0 0.0"/>
      <mass value="1"/>
      <inertia ixx="1.0" ixy="0.0" ixz="0.0" iyy="1.0" iyz="0.0" izz="1.0"/>
    </inertial>
  </link>

  <link name="tool">
    <visual>
      <origin rpy="0.0 0.0 0.0" xyz="0.0 0.0 0.0"/>
      <geometry>
	<cylinder length="0.03" radius="0.04" />
      </geometry>
      <material name="">
        <color rgba="0.0 0.8 0.0 1.0"/>
      </material>
    </visual>
    <collision>
      <origin rpy="0.0 0.0 0.0" xyz="0.0 0.0 0.0"/>
      <geometry>
        <cylinder length="0.03" radius="0.04" />
      </geometry>
    </collision>
    <inertial>
      <origin rpy="0.0 0.0 0.0" xyz="0.0 0.0 0.0"/>
      <mass value="1"/>
      <inertia ixx="1.0" ixy="0.0" ixz="0.0" iyy="1.0" iyz="0.0" izz="1.0"/>
    </inertial>
  </link>
  
  <joint name="shoulder_yaw" type="revolute">
    <origin rpy="0.0 0.0 0.0" xyz="0.0 0.0 0.0"/>
    <parent link="base_link"/>
    <child link="shoulder_preroll"/>
    <axis xyz="0 0 1"/>
    <limit effort="0" lower="-0.52" upper="1.04" velocity="1.0"/>
  </joint> 
  <joint name="shoulder_roll" type="revolute">
    <origin rpy="1.57079 0.0 0.0" xyz="0.0 0.0 0.107"/>
    <parent link="shoulder_preroll"/>
    <child link="shoulder"/>
    <axis xyz="0 0 1"/>
    <limit effort="0" lower="-0.55" upper="1.4" velocity="1.0"/>
  </joint> 
  <joint name="shoulder_pitch" type="revolute">
    <origin rpy="0 -1.57079 0.0" xyz="0.0 0.0 0.129"/>
    <parent link="shoulder"/>
    <child link="upperarm_preroll"/>
    <axis xyz="0 0 1"/>
    <limit effort="0" lower="0.0" upper="1.1" velocity="1.0"/>
  </joint>
  <joint name="upperarm_roll" type="revolute">
    <origin rpy="1.57079 0.0 0.0" xyz="0.0 -0.09 0.0"/>
    <parent link="upperarm_preroll"/>
    <child link="upperarm"/>
    <axis xyz="0 0 1"/>
    <limit effort="0" lower="-1.57080" upper="1.57080" velocity="1.0"/>
  </joint>
  <joint name="elbow" type="revolute">
    <origin rpy="0.0 1.57079 0.0" xyz="0.0 -0.0103 0.2035"/>
    <parent link="upperarm"/>
    <child link="lowerarm_preroll"/>
    <axis xyz="0 0 1"/>
    <limit effort="0" lower="-0.85" upper="0.65" velocity="1.0"/>
  </joint>
  <joint name="forearm_roll" type="revolute">
    <origin rpy="1.57079 0.0 0.0" xyz="0.0 -0.079 0.0"/>
    <parent link="lowerarm_preroll"/>
    <child link="lowerarm"/>
    <axis xyz="0 0 1"/>
    <limit effort="0" lower="-2.7489" upper="2.7489" velocity="1.0"/>
  </joint>
  <joint name="wrist_pitch" type="revolute">
    <origin rpy=" 0.0 1.57079 0.0" xyz="0.0 0.0 0.15"/>
    <parent link="lowerarm"/>
    <child link="wrist"/>
    <axis xyz="0 0 1"/>
    <limit effort="0" lower="-0.75" upper="0.5" velocity="1.0"/>
  </joint>
  <joint name="wrist_to_coupling" type="fixed">
    <origin rpy="0.0 0.0 3.14159" xyz="-0.0281 0.0 0.0"/>
    <parent link="wrist"/>
    <child link="coupling"/>
    <axis xyz="0 0 1"/>
    <limit effort="0" lower="-1.57080" upper="1.57080" velocity="1.0"/>
  </joint>
  <joint name="coupling_to_tool" type="fixed">
    <origin rpy="-1.57079 0.0 0.0" xyz="0.075 0.0 0.0"/>
    <parent link="coupling"/>
    <child link="tool"/>
    <axis xyz="0 0 1"/>
    <limit effort="0" lower="-1.57080" upper="1.57080" velocity="1.0"/>
  </joint>
  
</robot>
